2018-01-01 21:23:22,886 ERROR: Exception on /explore [GET] [in c:\meet_up\venv\lib\site-packages\flask\app.py:1560]
Traceback (most recent call last):
  File "c:\meet_up\venv\lib\site-packages\flask\app.py", line 1982, in wsgi_app
    response = self.full_dispatch_request()
  File "c:\meet_up\venv\lib\site-packages\flask\app.py", line 1614, in full_dispatch_request
    rv = self.handle_user_exception(e)
  File "c:\meet_up\venv\lib\site-packages\flask\app.py", line 1517, in handle_user_exception
    reraise(exc_type, exc_value, tb)
  File "c:\meet_up\venv\lib\site-packages\flask\_compat.py", line 33, in reraise
    raise value
  File "c:\meet_up\venv\lib\site-packages\flask\app.py", line 1612, in full_dispatch_request
    rv = self.dispatch_request()
  File "c:\meet_up\venv\lib\site-packages\flask\app.py", line 1598, in dispatch_request
    return self.view_functions[rule.endpoint](**req.view_args)
  File "c:\meet_up\venv\lib\site-packages\flask_login\utils.py", line 261, in decorated_view
    return func(*args, **kwargs)
  File "C:\meet_up\APP\routes.py", line 147, in explore
    next_url=next_url, prev_url=prev_url)
  File "c:\meet_up\venv\lib\site-packages\flask\templating.py", line 134, in render_template
    context, ctx.app)
  File "c:\meet_up\venv\lib\site-packages\flask\templating.py", line 116, in _render
    rv = template.render(context)
  File "c:\meet_up\venv\lib\site-packages\jinja2\asyncsupport.py", line 76, in render
    return original_render(self, *args, **kwargs)
  File "c:\meet_up\venv\lib\site-packages\jinja2\environment.py", line 1008, in render
    return self.environment.handle_exception(exc_info, True)
  File "c:\meet_up\venv\lib\site-packages\jinja2\environment.py", line 780, in handle_exception
    reraise(exc_type, exc_value, tb)
  File "c:\meet_up\venv\lib\site-packages\jinja2\_compat.py", line 37, in reraise
    raise value.with_traceback(tb)
  File "C:\meet_up\APP\templates\index.html", line 1, in top-level template code
    {% extends "base.html" %}
  File "C:\meet_up\APP\templates\base.html", line 31, in top-level template code
    {% block content %}
  File "C:\meet_up\APP\templates\index.html", line 19, in block "content"
    {% include '_post.html' %}
  File "C:\meet_up\APP\templates\_post.html", line 6, in top-level template code
    <td><a href="{{ url_for('user', username = post.author.username) }}">{{ post.author.username }}</a> says:
  File "c:\meet_up\venv\lib\site-packages\flask\helpers.py", line 333, in url_for
    return appctx.app.handle_url_build_error(error, endpoint, values)
  File "c:\meet_up\venv\lib\site-packages\flask\app.py", line 1805, in handle_url_build_error
    reraise(exc_type, exc_value, tb)
  File "c:\meet_up\venv\lib\site-packages\flask\_compat.py", line 33, in reraise
    raise value
  File "c:\meet_up\venv\lib\site-packages\flask\helpers.py", line 323, in url_for
    force_external=external)
  File "c:\meet_up\venv\lib\site-packages\werkzeug\routing.py", line 1768, in build
    raise BuildError(endpoint, values, method, self)
werkzeug.routing.BuildError: Could not build url for endpoint 'user'. Did you forget to specify values ['username']?
2018-01-01 21:23:46,795 INFO: meetup startup [in C:\meet_up\APP\__init__.py:48]
2018-01-01 21:27:12,302 INFO: meetup startup [in C:\meet_up\APP\__init__.py:48]
2018-01-01 21:27:17,041 INFO: meetup startup [in C:\meet_up\APP\__init__.py:48]
2018-01-01 21:35:11,272 INFO: meetup startup [in C:\meet_up\APP\__init__.py:48]
2018-01-01 21:37:05,554 INFO: meetup startup [in C:\meet_up\APP\__init__.py:48]
2018-01-01 22:10:01,259 INFO: meetup startup [in C:\meet_up\APP\__init__.py:48]
2018-01-03 18:03:57,824 INFO: meetup startup [in C:\meet_up\APP\__init__.py:48]
2018-01-05 19:47:56,924 INFO: meetup startup [in C:\meet_up\APP\__init__.py:50]
